<?xml version="1.0" encoding="utf-8"?>
<!-- =================================================================================== -->
<!-- |    This document was autogenerated by xacro from quadruped_robot.urdf.xacro     | -->
<!-- |    EDITING THIS FILE BY HAND IS NOT RECOMMENDED                                 | -->
<!-- =================================================================================== -->
<robot name="quadruped_robot">
  <link name="quadruped_frame">
    <visual>
      <geometry>
        <mesh filename="./mesh/frames/quadruped_horizontal.obj" scale="0.001 0.001 0.001"/>
      </geometry>
    </visual>
    <collision>
      <geometry>
        <mesh filename="./mesh/frames/quadruped_horizontal.obj" scale="0.001 0.001 0.001"/>
      </geometry>
    </collision>
    <inertial>
      <mass value="0.1993557037"/>
      <origin xyz="0 0 -0.0002889412"/>
      <inertia ixx="0.0029510715" ixy="0.0" ixz="-2e-10" iyy="0.0004986724" iyz="-0.0" izz="0.0030511616"/>
    </inertial>
  </link>
  <link name="left_0-xm430_0">
    <inertial>
      <origin rpy="0 0 0" xyz="-4.0773796e-3 -1.5304911e-2 -1.6871895e-2"/>
      <mass value="0.082"/>
      <inertia ixx="2.3729564e-5" ixy="-1.3079758e-7" ixz="-8.1403365e-8" iyy="1.3112295e-5" iyz="-1.9659314e-6" izz="2.0942871e-5"/>
    </inertial>
    <visual>
      <origin rpy="0.0 0.0 0.0" xyz="0.0 0.0 0.0"/>
      <geometry>
        <mesh filename="./mesh/general/XM430-simplified.stl" scale="0.001 0.001 0.001"/>
      </geometry>
    </visual>
    <collision>
      <origin rpy="0.0 0.0 0.0" xyz="0.0 0.0 0.0"/>
      <geometry>
        <mesh filename="./mesh/general/XM430-simplified.stl" scale="0.001 0.001 0.001"/>
      </geometry>
    </collision>
  </link>
  <link name="left_0-xm430_1">
    <inertial>
      <origin rpy="0 0 0" xyz="-4.0773796e-3 -1.5304911e-2 -1.6871895e-2"/>
      <mass value="0.082"/>
      <inertia ixx="2.3729564e-5" ixy="-1.3079758e-7" ixz="-8.1403365e-8" iyy="1.3112295e-5" iyz="-1.9659314e-6" izz="2.0942871e-5"/>
    </inertial>
    <visual>
      <origin rpy="0.0 0.0 0.0" xyz="0.0 0.0 0.0"/>
      <geometry>
        <mesh filename="./mesh/general/XM430-simplified.stl" scale="0.001 0.001 0.001"/>
      </geometry>
    </visual>
    <collision>
      <origin rpy="0.0 0.0 0.0" xyz="0.0 0.0 0.0"/>
      <geometry>
        <mesh filename="./mesh/general/XM430-simplified.stl" scale="0.001 0.001 0.001"/>
      </geometry>
    </collision>
  </link>
  <link name="left_0-xm430_2">
    <inertial>
      <origin rpy="0 0 0" xyz="-4.0773796e-3 -1.5304911e-2 -1.6871895e-2"/>
      <mass value="0.082"/>
      <inertia ixx="2.3729564e-5" ixy="-1.3079758e-7" ixz="-8.1403365e-8" iyy="1.3112295e-5" iyz="-1.9659314e-6" izz="2.0942871e-5"/>
    </inertial>
    <visual>
      <origin rpy="0.0 0.0 0.0" xyz="0.0 0.0 0.0"/>
      <geometry>
        <mesh filename="./mesh/general/XM430-simplified.stl" scale="0.001 0.001 0.001"/>
      </geometry>
    </visual>
    <collision>
      <origin rpy="0.0 0.0 0.0" xyz="0.0 0.0 0.0"/>
      <geometry>
        <mesh filename="./mesh/general/XM430-simplified.stl" scale="0.001 0.001 0.001"/>
      </geometry>
    </collision>
  </link>
  <link name="left_0-base_motor_frame">
    <inertial>
      <origin rpy="0 0 0" xyz="6.48e-08 -0.0015864406 0.0250889877"/>
      <mass value="0.0768049156"/>
      <inertia ixx="5.65659e-05" ixy="-0.0" ixz="1e-10" iyy="5.30145e-05" iyz="1.1663e-06" izz="3.40217e-05"/>
    </inertial>
    <visual>
      <origin rpy="0 0 0" xyz="0 0 0"/>
      <geometry>
        <mesh filename="./mesh/general/base_motor_frame_simplified.stl" scale="0.001 0.001 0.001"/>
      </geometry>
    </visual>
    <collision>
      <origin rpy="0 0 0" xyz="0 0 0"/>
      <geometry>
        <mesh filename="./mesh/general/base_motor_frame_simplified.stl" scale="0.001 0.001 0.001"/>
      </geometry>
    </collision>
  </link>
  <link name="left_0-dual_servo_shell">
    <inertial>
      <origin rpy="0 0 0" xyz="0.0005322566 -0.0003161331 0.0506920676"/>
      <mass value="0.0258069457"/>
      <inertia ixx="4.11451e-05" ixy="7.82e-08" ixz="-7.721e-07" iyy="4.42386e-05" iyz="2.774e-07" izz="4.8477e-06"/>
    </inertial>
    <visual>
      <origin rpy="0.0 0.0 0.0" xyz="0.0 0.0 0.0"/>
      <geometry>
        <mesh filename="./mesh/general/dual_servo_shell_simplified.stl" scale="0.001 0.001 0.001"/>
      </geometry>
    </visual>
    <collision>
      <origin rpy="0.0 0.0 0.0" xyz="0.0 0.0 0.0"/>
      <geometry>
        <mesh filename="./mesh/general/dual_servo_shell_simplified.stl" scale="0.001 0.001 0.001"/>
      </geometry>
    </collision>
  </link>
  <link name="left_0-dual_servo_transmission">
    <inertial>
      <origin rpy="0 0 0" xyz="-1.41e-08 0.0095354556 0.0141401617"/>
      <mass value="0.0576887165"/>
      <inertia ixx="2.78223e-05" ixy="5.7e-09" ixz="-0.0" iyy="1.35978e-05" iyz="4.5419e-06" izz="2.50167e-05"/>
    </inertial>
    <visual>
      <origin rpy="0.0 0.0 0.0" xyz="0.0 0.0 0.0"/>
      <geometry>
        <mesh filename="./mesh/general/dual_servo_transmission_simplified.obj" scale="0.001 0.001 0.001"/>
      </geometry>
    </visual>
    <collision>
      <origin rpy="0.0 0.0 0.0" xyz="0.0 0.0 0.0"/>
      <geometry>
        <mesh filename="./mesh/general/dual_servo_transmission_simplified.obj" scale="0.001 0.001 0.001"/>
      </geometry>
    </collision>
  </link>
  <link name="left_0-link1">
    <inertial>
      <origin rpy="0 0 0" xyz="0.0024455616 -0.0613330624 -0.0010832509"/>
      <mass value="0.0299338616"/>
      <inertia ixx="5.2023e-05" ixy="2.0911e-06" ixz="4.522e-07" iyy="1.979e-06" iyz="-5.3953e-06" izz="5.17237e-05"/>
    </inertial>
    <visual>
      <origin rpy="0.0 0.0 0.0" xyz="0.0 0.0 0.0"/>
      <geometry>
        <mesh filename="./mesh/overconstrained/link1.obj" scale="0.001 0.001 0.001"/>
      </geometry>
    </visual>
    <collision>
      <origin rpy="0.0 0.0 0.0" xyz="0.0 0.0 0.0"/>
      <geometry>
        <mesh filename="./mesh/overconstrained/link1.obj" scale="0.001 0.001 0.001"/>
      </geometry>
    </collision>
  </link>
  <link name="left_0-link2">
    <inertial>
      <origin rpy="0 0 0" xyz="0.0025704082 -0.0645378917 0.0038718462"/>
      <mass value="0.02848145"/>
      <inertia ixx="4.53813e-05" ixy="1.8569e-06" ixz="-1.651e-07" iyy="1.3363e-06" iyz="-1.3281e-06" izz="4.55555e-05"/>
    </inertial>
    <visual>
      <origin rpy="0.0 0.0 0.0" xyz="0.0 0.0 0.0"/>
      <geometry>
        <mesh filename="./mesh/overconstrained/link2.obj" scale="0.001 0.001 0.001"/>
      </geometry>
    </visual>
    <collision>
      <origin rpy="0.0 0.0 0.0" xyz="0.0 0.0 0.0"/>
      <geometry>
        <mesh filename="./mesh/overconstrained/link2.obj" scale="0.001 0.001 0.001"/>
      </geometry>
    </collision>
  </link>
  <link name="left_0-link4">
    <inertial>
      <origin rpy="0 0 0" xyz="-0.0026422902 -0.067590774 -0.0033849791"/>
      <mass value="0.0275608119"/>
      <inertia ixx="3.84633e-05" ixy="-1.6444e-06" ixz="-2.013e-07" iyy="1.4218e-06" iyz="4.345e-07" izz="3.88256e-05"/>
    </inertial>
    <visual>
      <origin rpy="0.0 0.0 0.0" xyz="0.0 0.0 0.0"/>
      <geometry>
        <mesh filename="./mesh/overconstrained/link4.obj" scale="0.001 0.001 0.001"/>
      </geometry>
    </visual>
    <collision>
      <origin rpy="0.0 0.0 0.0" xyz="0.0 0.0 0.0"/>
      <geometry>
        <mesh filename="./mesh/overconstrained/link4.obj" scale="0.001 0.001 0.001"/>
      </geometry>
    </collision>
  </link>
  <link name="left_0-link3">
    <inertial>
      <origin rpy="0 0 0" xyz="0.002386501 -0.0533785592 -0.0003073645"/>
      <mass value="0.0217645964"/>
      <inertia ixx="3.57111e-05" ixy="1.7199e-06" ixz="1.471e-07" iyy="1.2113e-06" iyz="-4.1867e-06" izz="3.54138e-05"/>
    </inertial>
    <visual>
      <origin rpy="0.0 0.0 0.0" xyz="0.0 0.0 0.0"/>
      <geometry>
        <mesh filename="./mesh/overconstrained/link3.obj" scale="0.001 0.001 0.001"/>
      </geometry>
    </visual>
    <collision>
      <origin rpy="0.0 0.0 0.0" xyz="0.0 0.0 0.0"/>
      <geometry>
        <mesh filename="./mesh/overconstrained/link3.obj" scale="0.001 0.001 0.001"/>
      </geometry>
    </collision>
  </link>
  <!--Create joints to connect the parts-->
  <!--Fix the module to module parent link-->
  <joint name="left_0-module_to_parent" type="fixed">
    <parent link="quadruped_frame"/>
    <child link="left_0-base_motor_frame"/>
    <origin rpy="1.570796325 -2.3561944875 0" xyz="-0.03875 0.0025 0"/>
  </joint>
  <!--Fix the parts which are not supposed to move-->
  <joint name="left_0-fix_xm430_0" type="fixed">
    <parent link="left_0-base_motor_frame"/>
    <child link="left_0-xm430_0"/>
    <origin rpy="0 0 0" xyz="0 0 0.054"/>
  </joint>
  <joint name="left_0-fix_xm430_1" type="fixed">
    <parent link="left_0-dual_servo_shell"/>
    <child link="left_0-xm430_1"/>
    <origin rpy="-1.570796325 0 0" xyz="0 0.019 0.0334"/>
  </joint>
  <joint name="left_0-fix_xm430_2" type="fixed">
    <parent link="left_0-xm430_1"/>
    <child link="left_0-xm430_2"/>
    <origin rpy="0 0 0" xyz="0 -0.0465 0"/>
  </joint>
  <joint name="left_0-fix_transmission" type="fixed">
    <parent link="left_0-xm430_2"/>
    <child link="left_0-dual_servo_transmission"/>
    <origin rpy="0 0 0" xyz="0 0 0"/>
  </joint>
  <!--DoFs, joints corresponding to the degrees of actuation-->
  <joint name="left_0-dof1" type="revolute">
    <parent link="left_0-xm430_0"/>
    <child link="left_0-dual_servo_shell"/>
    <axis xyz="0 0 -1"/>
    <limit effort="1000" lower="-3.14159265" upper="3.14159265" velocity="1000"/>
    <origin rpy="0 0 0" xyz="0 0 0"/>
  </joint>
  <joint name="left_0-dof2" type="revolute">
    <parent link="left_0-xm430_2"/>
    <child link="left_0-link4"/>
    <axis xyz="0 0 -1"/>
    <limit effort="1000" lower="-1.570796325" upper="1.570796325" velocity="1000"/>
    <origin rpy="0 0 0" xyz="0 0 0.0368"/>
  </joint>
  <joint name="left_0-dof3" type="revolute">
    <parent link="left_0-xm430_2"/>
    <child link="left_0-link1"/>
    <axis xyz="0 0 -1"/>
    <limit effort="1000" lower="-1.570796325" upper="1.570796325" velocity="1000"/>
    <origin rpy="0 0 0" xyz="0 0 0.0388"/>
  </joint>
  <joint name="left_0-link4_to_link3" type="revolute">
    <parent link="left_0-link4"/>
    <child link="left_0-link3"/>
    <axis xyz="0 0 1"/>
    <limit effort="1000" lower="-2.3561944875" upper="2.3561944875" velocity="1000"/>
    <origin rpy="0 0.7853981625 0" xyz="0.0014142 -0.1 0.0014142"/>
  </joint>
  <joint name="left_0-link1_to_link2" type="revolute">
    <parent link="left_0-link1"/>
    <child link="left_0-link2"/>
    <axis xyz="0 0 1"/>
    <limit effort="1000" lower="-2.3561944875" upper="2.3561944875" velocity="1000"/>
    <origin rpy="0 -0.7853981625 0" xyz="-0.000707 -0.1 -0.000293"/>
  </joint>
  <!--For closed chain construction-->
  <link name="left_0-link2_intermediate"/>
  <joint name="left_0-link2_intermediate_fixed" type="fixed">
    <parent link="left_0-link2"/>
    <child link="left_0-link2_intermediate"/>
    <origin rpy="0 0.7853981625 0" xyz="0 -0.1 -0.001"/>
  </joint>
  <link name="left_0-link3_intermediate"/>
  <joint name="left_0-link3_intermediate_fixed" type="fixed">
    <parent link="left_0-link3"/>
    <child link="left_0-link3_intermediate"/>
    <origin rpy="0 -0.7853981625 0" xyz="0 -0.1 -0.001"/>
  </joint>
  <joint name="left_0-closed_chain_revolute" type="revolute">
    <parent link="left_0-link3_intermediate"/>
    <child link="left_0-link2_intermediate"/>
    <axis xyz="0 0 1"/>
    <limit effort="1000" lower="-3.14159265" upper="3.14159265" velocity="1000"/>
  </joint>
  <!--frames that may be helpful-->
  <link name="left_0-fingertip_frame">
    <geometry>
      <origin rpy="0 0 0" xyz="0 0 0"/>
    </geometry>
  </link>
  <joint name="left_0-fingertip_frame_fix" type="fixed">
    <parent link="left_0-link3"/>
    <child link="left_0-fingertip_frame"/>
    <origin rpy="0 0 0" xyz="0.004243 -0.127 -0.005243"/>
  </joint>
  <link name="right_0-xm430_0">
    <inertial>
      <origin rpy="0 0 0" xyz="-4.0773796e-3 -1.5304911e-2 -1.6871895e-2"/>
      <mass value="0.082"/>
      <inertia ixx="2.3729564e-5" ixy="-1.3079758e-7" ixz="-8.1403365e-8" iyy="1.3112295e-5" iyz="-1.9659314e-6" izz="2.0942871e-5"/>
    </inertial>
    <visual>
      <origin rpy="0.0 0.0 0.0" xyz="0.0 0.0 0.0"/>
      <geometry>
        <mesh filename="./mesh/general/XM430-simplified.stl" scale="0.001 0.001 0.001"/>
      </geometry>
    </visual>
    <collision>
      <origin rpy="0.0 0.0 0.0" xyz="0.0 0.0 0.0"/>
      <geometry>
        <mesh filename="./mesh/general/XM430-simplified.stl" scale="0.001 0.001 0.001"/>
      </geometry>
    </collision>
  </link>
  <link name="right_0-xm430_1">
    <inertial>
      <origin rpy="0 0 0" xyz="-4.0773796e-3 -1.5304911e-2 -1.6871895e-2"/>
      <mass value="0.082"/>
      <inertia ixx="2.3729564e-5" ixy="-1.3079758e-7" ixz="-8.1403365e-8" iyy="1.3112295e-5" iyz="-1.9659314e-6" izz="2.0942871e-5"/>
    </inertial>
    <visual>
      <origin rpy="0.0 0.0 0.0" xyz="0.0 0.0 0.0"/>
      <geometry>
        <mesh filename="./mesh/general/XM430-simplified.stl" scale="0.001 0.001 0.001"/>
      </geometry>
    </visual>
    <collision>
      <origin rpy="0.0 0.0 0.0" xyz="0.0 0.0 0.0"/>
      <geometry>
        <mesh filename="./mesh/general/XM430-simplified.stl" scale="0.001 0.001 0.001"/>
      </geometry>
    </collision>
  </link>
  <link name="right_0-xm430_2">
    <inertial>
      <origin rpy="0 0 0" xyz="-4.0773796e-3 -1.5304911e-2 -1.6871895e-2"/>
      <mass value="0.082"/>
      <inertia ixx="2.3729564e-5" ixy="-1.3079758e-7" ixz="-8.1403365e-8" iyy="1.3112295e-5" iyz="-1.9659314e-6" izz="2.0942871e-5"/>
    </inertial>
    <visual>
      <origin rpy="0.0 0.0 0.0" xyz="0.0 0.0 0.0"/>
      <geometry>
        <mesh filename="./mesh/general/XM430-simplified.stl" scale="0.001 0.001 0.001"/>
      </geometry>
    </visual>
    <collision>
      <origin rpy="0.0 0.0 0.0" xyz="0.0 0.0 0.0"/>
      <geometry>
        <mesh filename="./mesh/general/XM430-simplified.stl" scale="0.001 0.001 0.001"/>
      </geometry>
    </collision>
  </link>
  <link name="right_0-base_motor_frame">
    <inertial>
      <origin rpy="0 0 0" xyz="6.48e-08 -0.0015864406 0.0250889877"/>
      <mass value="0.0768049156"/>
      <inertia ixx="5.65659e-05" ixy="-0.0" ixz="1e-10" iyy="5.30145e-05" iyz="1.1663e-06" izz="3.40217e-05"/>
    </inertial>
    <visual>
      <origin rpy="0 0 0" xyz="0 0 0"/>
      <geometry>
        <mesh filename="./mesh/general/base_motor_frame_simplified.stl" scale="0.001 0.001 0.001"/>
      </geometry>
    </visual>
    <collision>
      <origin rpy="0 0 0" xyz="0 0 0"/>
      <geometry>
        <mesh filename="./mesh/general/base_motor_frame_simplified.stl" scale="0.001 0.001 0.001"/>
      </geometry>
    </collision>
  </link>
  <link name="right_0-dual_servo_shell">
    <inertial>
      <origin rpy="0 0 0" xyz="0.0005322566 -0.0003161331 0.0506920676"/>
      <mass value="0.0258069457"/>
      <inertia ixx="4.11451e-05" ixy="7.82e-08" ixz="-7.721e-07" iyy="4.42386e-05" iyz="2.774e-07" izz="4.8477e-06"/>
    </inertial>
    <visual>
      <origin rpy="0.0 0.0 0.0" xyz="0.0 0.0 0.0"/>
      <geometry>
        <mesh filename="./mesh/general/dual_servo_shell_simplified.stl" scale="0.001 0.001 0.001"/>
      </geometry>
    </visual>
    <collision>
      <origin rpy="0.0 0.0 0.0" xyz="0.0 0.0 0.0"/>
      <geometry>
        <mesh filename="./mesh/general/dual_servo_shell_simplified.stl" scale="0.001 0.001 0.001"/>
      </geometry>
    </collision>
  </link>
  <link name="right_0-dual_servo_transmission">
    <inertial>
      <origin rpy="0 0 0" xyz="-1.41e-08 0.0095354556 0.0141401617"/>
      <mass value="0.0576887165"/>
      <inertia ixx="2.78223e-05" ixy="5.7e-09" ixz="-0.0" iyy="1.35978e-05" iyz="4.5419e-06" izz="2.50167e-05"/>
    </inertial>
    <visual>
      <origin rpy="0.0 0.0 0.0" xyz="0.0 0.0 0.0"/>
      <geometry>
        <mesh filename="./mesh/general/dual_servo_transmission_simplified.obj" scale="0.001 0.001 0.001"/>
      </geometry>
    </visual>
    <collision>
      <origin rpy="0.0 0.0 0.0" xyz="0.0 0.0 0.0"/>
      <geometry>
        <mesh filename="./mesh/general/dual_servo_transmission_simplified.obj" scale="0.001 0.001 0.001"/>
      </geometry>
    </collision>
  </link>
  <link name="right_0-link1">
    <inertial>
      <origin rpy="0 0 0" xyz="0.0024455616 -0.0613330624 -0.0010832509"/>
      <mass value="0.0299338616"/>
      <inertia ixx="5.2023e-05" ixy="2.0911e-06" ixz="4.522e-07" iyy="1.979e-06" iyz="-5.3953e-06" izz="5.17237e-05"/>
    </inertial>
    <visual>
      <origin rpy="0.0 0.0 0.0" xyz="0.0 0.0 0.0"/>
      <geometry>
        <mesh filename="./mesh/overconstrained/link1.obj" scale="0.001 0.001 0.001"/>
      </geometry>
    </visual>
    <collision>
      <origin rpy="0.0 0.0 0.0" xyz="0.0 0.0 0.0"/>
      <geometry>
        <mesh filename="./mesh/overconstrained/link1.obj" scale="0.001 0.001 0.001"/>
      </geometry>
    </collision>
  </link>
  <link name="right_0-link2_right">
    <inertial>
      <origin rpy="0 0 0" xyz="-0.0023861897 -0.0533785446 -0.0003074935"/>
      <mass value="0.0217645905"/>
      <inertia ixx="3.57112e-05" ixy="-1.7195e-06" ixz="-1.471e-07" iyy="1.2113e-06" iyz="-4.186e-06" izz="3.54138e-05"/>
    </inertial>
    <visual>
      <origin rpy="0.0 0.0 0.0" xyz="0.0 0.0 0.0"/>
      <geometry>
        <mesh filename="./mesh/overconstrained/link2_right.obj" scale="0.001 0.001 0.001"/>
      </geometry>
    </visual>
    <collision>
      <origin rpy="0.0 0.0 0.0" xyz="0.0 0.0 0.0"/>
      <geometry>
        <mesh filename="./mesh/overconstrained/link2_right.obj" scale="0.001 0.001 0.001"/>
      </geometry>
    </collision>
  </link>
  <link name="right_0-link4">
    <inertial>
      <origin rpy="0 0 0" xyz="-0.0026422902 -0.067590774 -0.0033849791"/>
      <mass value="0.0275608119"/>
      <inertia ixx="3.84633e-05" ixy="-1.6444e-06" ixz="-2.013e-07" iyy="1.4218e-06" iyz="4.345e-07" izz="3.88256e-05"/>
    </inertial>
    <visual>
      <origin rpy="0.0 0.0 0.0" xyz="0.0 0.0 0.0"/>
      <geometry>
        <mesh filename="./mesh/overconstrained/link4.obj" scale="0.001 0.001 0.001"/>
      </geometry>
    </visual>
    <collision>
      <origin rpy="0.0 0.0 0.0" xyz="0.0 0.0 0.0"/>
      <geometry>
        <mesh filename="./mesh/overconstrained/link4.obj" scale="0.001 0.001 0.001"/>
      </geometry>
    </collision>
  </link>
  <link name="right_0-link3_right">
    <inertial>
      <origin rpy="0 0 0" xyz="-0.0025702692 -0.0645378917 0.0038718462"/>
      <mass value="0.02848145"/>
      <inertia ixx="4.53813e-05" ixy="-1.8558e-06" ixz="1.652e-07" iyy="1.3363e-06" iyz="-1.3281e-06" izz="4.55555e-05"/>
    </inertial>
    <visual>
      <origin rpy="0.0 0.0 0.0" xyz="0.0 0.0 0.0"/>
      <geometry>
        <mesh filename="./mesh/overconstrained/link3_right.obj" scale="0.001 0.001 0.001"/>
      </geometry>
    </visual>
    <collision>
      <origin rpy="0.0 0.0 0.0" xyz="0.0 0.0 0.0"/>
      <geometry>
        <mesh filename="./mesh/overconstrained/link3_right.obj" scale="0.001 0.001 0.001"/>
      </geometry>
    </collision>
  </link>
  <!--Create joints to connect the parts-->
  <!--Fix the module to module parent link-->
  <joint name="right_0-module_to_parent" type="fixed">
    <parent link="quadruped_frame"/>
    <child link="right_0-base_motor_frame"/>
    <origin rpy="1.570796325 2.3561944875 0" xyz="0.03875 0.0025 0"/>
  </joint>
  <!--Fix the parts which are not supposed to move-->
  <joint name="right_0-fix_xm430_0" type="fixed">
    <parent link="right_0-base_motor_frame"/>
    <child link="right_0-xm430_0"/>
    <origin rpy="0 0 0" xyz="0 0 0.054"/>
  </joint>
  <joint name="right_0-fix_xm430_1" type="fixed">
    <parent link="right_0-dual_servo_shell"/>
    <child link="right_0-xm430_1"/>
    <origin rpy="-1.570796325 0 0" xyz="0 0.019 0.0334"/>
  </joint>
  <joint name="right_0-fix_xm430_2" type="fixed">
    <parent link="right_0-xm430_1"/>
    <child link="right_0-xm430_2"/>
    <origin rpy="0 0 0" xyz="0 -0.0465 0"/>
  </joint>
  <joint name="right_0-fix_transmission" type="fixed">
    <parent link="right_0-xm430_2"/>
    <child link="right_0-dual_servo_transmission"/>
    <origin rpy="0 0 0" xyz="0 0 0"/>
  </joint>
  <!--DoFs, joints corresponding to the degrees of actuation-->
  <joint name="right_0-dof1" type="revolute">
    <parent link="right_0-xm430_0"/>
    <child link="right_0-dual_servo_shell"/>
    <axis xyz="0 0 -1"/>
    <limit effort="1000" lower="-3.14159265" upper="3.14159265" velocity="1000"/>
    <origin rpy="0 0 0" xyz="0 0 0"/>
  </joint>
  <joint name="right_0-dof2" type="revolute">
    <parent link="right_0-xm430_2"/>
    <child link="right_0-link4"/>
    <axis xyz="0 0 -1"/>
    <limit effort="1000" lower="-1.570796325" upper="1.570796325" velocity="1000"/>
    <origin rpy="0 0 0" xyz="0 0 0.0368"/>
  </joint>
  <joint name="right_0-dof3" type="revolute">
    <parent link="right_0-xm430_2"/>
    <child link="right_0-link1"/>
    <axis xyz="0 0 -1"/>
    <limit effort="1000" lower="-1.570796325" upper="1.570796325" velocity="1000"/>
    <origin rpy="0 0 0" xyz="0 0 0.0388"/>
  </joint>
  <joint name="right_0-link4_to_link3_right" type="revolute">
    <parent link="right_0-link4"/>
    <child link="right_0-link3_right"/>
    <axis xyz="0 0 1"/>
    <limit effort="1000" lower="-2.3561944875" upper="2.3561944875" velocity="1000"/>
    <origin rpy="0 0.7853981625 0" xyz="0.000707 -0.1 0.001707"/>
  </joint>
  <joint name="right_0-link1_to_link2_right" type="revolute">
    <parent link="right_0-link1"/>
    <child link="right_0-link2_right"/>
    <axis xyz="0 0 1"/>
    <limit effort="1000" lower="-2.3561944875" upper="2.3561944875" velocity="1000"/>
    <origin rpy="0 -0.7853981625 0" xyz="-0.000707 -0.1 -0.000293"/>
  </joint>
  <!--For closed chain construction-->
  <link name="right_0-link2_intermediate"/>
  <joint name="right_0-link2_intermediate_fixed" type="fixed">
    <parent link="right_0-link2_right"/>
    <child link="right_0-link2_intermediate"/>
    <origin rpy="0 0.7853981625 0" xyz="0 -0.1 -0.001"/>
  </joint>
  <link name="right_0-link3_intermediate"/>
  <joint name="right_0-link3_intermediate_fixed" type="fixed">
    <parent link="right_0-link3_right"/>
    <child link="right_0-link3_intermediate"/>
    <origin rpy="0 -0.7853981625 0" xyz="0 -0.1 -0.001"/>
  </joint>
  <joint name="right_0-closed_chain_revolute" type="revolute">
    <parent link="right_0-link3_intermediate"/>
    <child link="right_0-link2_intermediate"/>
    <axis xyz="0 0 1"/>
    <limit effort="1000" lower="-3.14159265" upper="3.14159265" velocity="1000"/>
  </joint>
  <!--frames that may be helpful-->
  <link name="right_0-fingertip_frame">
    <geometry>
      <origin rpy="0 0 0" xyz="0 0 0"/>
    </geometry>
  </link>
  <joint name="right_0-fingertip_frame_fix" type="fixed">
    <parent link="right_0-link3_right"/>
    <child link="right_0-fingertip_frame"/>
    <origin rpy="0 0 0" xyz="0.004243 -0.127 -0.005243"/>
  </joint>
</robot>
